2018-05-06 22:02:00,349 INFO:             errors [in app.py:50]
2018-05-06 22:02:23,539 ERROR:             Exception on /favicon.ico [GET] [in /anaconda3/lib/python3.6/site-packages/flask/app.py:1560]
Traceback (most recent call last):
  File "/anaconda3/lib/python3.6/site-packages/flask/app.py", line 1982, in wsgi_app
    response = self.full_dispatch_request()
  File "/anaconda3/lib/python3.6/site-packages/flask/app.py", line 1615, in full_dispatch_request
    return self.finalize_request(rv)
  File "/anaconda3/lib/python3.6/site-packages/flask/app.py", line 1630, in finalize_request
    response = self.make_response(rv)
  File "/anaconda3/lib/python3.6/site-packages/flask/app.py", line 1725, in make_response
    raise ValueError('View function did not return a response')
ValueError: View function did not return a response
2018-05-06 22:03:08,155 ERROR:             Exception on /users/piusraj/documents/python_files/sample2.jpg [GET] [in /anaconda3/lib/python3.6/site-packages/flask/app.py:1560]
Traceback (most recent call last):
  File "/anaconda3/lib/python3.6/site-packages/flask/app.py", line 1982, in wsgi_app
    response = self.full_dispatch_request()
  File "/anaconda3/lib/python3.6/site-packages/flask/app.py", line 1615, in full_dispatch_request
    return self.finalize_request(rv)
  File "/anaconda3/lib/python3.6/site-packages/flask/app.py", line 1630, in finalize_request
    response = self.make_response(rv)
  File "/anaconda3/lib/python3.6/site-packages/flask/app.py", line 1725, in make_response
    raise ValueError('View function did not return a response')
ValueError: View function did not return a response
2018-05-06 22:03:47,704 ERROR:             Exception on /users/piusraj/documents/Python_files/sample2.jpg [GET] [in /anaconda3/lib/python3.6/site-packages/flask/app.py:1560]
Traceback (most recent call last):
  File "/anaconda3/lib/python3.6/site-packages/flask/app.py", line 1982, in wsgi_app
    response = self.full_dispatch_request()
  File "/anaconda3/lib/python3.6/site-packages/flask/app.py", line 1615, in full_dispatch_request
    return self.finalize_request(rv)
  File "/anaconda3/lib/python3.6/site-packages/flask/app.py", line 1630, in finalize_request
    response = self.make_response(rv)
  File "/anaconda3/lib/python3.6/site-packages/flask/app.py", line 1725, in make_response
    raise ValueError('View function did not return a response')
ValueError: View function did not return a response
2018-05-06 22:18:28,947 INFO:             errors [in app.py:50]
2018-05-06 22:26:14,887 INFO:             errors [in app.py:51]
2018-05-06 22:33:52,923 ERROR:             Exception on /asdasda [GET] [in /anaconda3/lib/python3.6/site-packages/flask/app.py:1560]
Traceback (most recent call last):
  File "/anaconda3/lib/python3.6/site-packages/flask/app.py", line 1982, in wsgi_app
    response = self.full_dispatch_request()
  File "/anaconda3/lib/python3.6/site-packages/flask/app.py", line 1615, in full_dispatch_request
    return self.finalize_request(rv)
  File "/anaconda3/lib/python3.6/site-packages/flask/app.py", line 1630, in finalize_request
    response = self.make_response(rv)
  File "/anaconda3/lib/python3.6/site-packages/flask/app.py", line 1725, in make_response
    raise ValueError('View function did not return a response')
ValueError: View function did not return a response
2018-05-06 22:33:57,912 ERROR:             Exception on /23412342134 [GET] [in /anaconda3/lib/python3.6/site-packages/flask/app.py:1560]
Traceback (most recent call last):
  File "/anaconda3/lib/python3.6/site-packages/flask/app.py", line 1982, in wsgi_app
    response = self.full_dispatch_request()
  File "/anaconda3/lib/python3.6/site-packages/flask/app.py", line 1615, in full_dispatch_request
    return self.finalize_request(rv)
  File "/anaconda3/lib/python3.6/site-packages/flask/app.py", line 1630, in finalize_request
    response = self.make_response(rv)
  File "/anaconda3/lib/python3.6/site-packages/flask/app.py", line 1725, in make_response
    raise ValueError('View function did not return a response')
ValueError: View function did not return a response
2018-05-07 08:06:09,494 ERROR:             Exception on /asdasda [GET] [in /anaconda3/lib/python3.6/site-packages/flask/app.py:1560]
Traceback (most recent call last):
  File "/anaconda3/lib/python3.6/site-packages/flask/app.py", line 1982, in wsgi_app
    response = self.full_dispatch_request()
  File "/anaconda3/lib/python3.6/site-packages/flask/app.py", line 1615, in full_dispatch_request
    return self.finalize_request(rv)
  File "/anaconda3/lib/python3.6/site-packages/flask/app.py", line 1630, in finalize_request
    response = self.make_response(rv)
  File "/anaconda3/lib/python3.6/site-packages/flask/app.py", line 1725, in make_response
    raise ValueError('View function did not return a response')
ValueError: View function did not return a response
2018-05-07 08:19:30,739 ERROR:             Exception on /sdafasdf [GET] [in /anaconda3/lib/python3.6/site-packages/flask/app.py:1560]
Traceback (most recent call last):
  File "/anaconda3/lib/python3.6/site-packages/flask/app.py", line 1982, in wsgi_app
    response = self.full_dispatch_request()
  File "/anaconda3/lib/python3.6/site-packages/flask/app.py", line 1615, in full_dispatch_request
    return self.finalize_request(rv)
  File "/anaconda3/lib/python3.6/site-packages/flask/app.py", line 1630, in finalize_request
    response = self.make_response(rv)
  File "/anaconda3/lib/python3.6/site-packages/flask/app.py", line 1725, in make_response
    raise ValueError('View function did not return a response')
ValueError: View function did not return a response
2018-05-07 15:16:03,112 INFO:             errors [in app.py:56]
2018-05-07 15:17:39,332 ERROR:             Exception on /favicon.ico [GET] [in /anaconda3/lib/python3.6/site-packages/flask/app.py:1560]
Traceback (most recent call last):
  File "/anaconda3/lib/python3.6/site-packages/flask/app.py", line 1982, in wsgi_app
    response = self.full_dispatch_request()
  File "/anaconda3/lib/python3.6/site-packages/flask/app.py", line 1615, in full_dispatch_request
    return self.finalize_request(rv)
  File "/anaconda3/lib/python3.6/site-packages/flask/app.py", line 1630, in finalize_request
    response = self.make_response(rv)
  File "/anaconda3/lib/python3.6/site-packages/flask/app.py", line 1725, in make_response
    raise ValueError('View function did not return a response')
ValueError: View function did not return a response
2018-05-07 15:17:51,590 ERROR:             Exception on /favicon.ico [GET] [in /anaconda3/lib/python3.6/site-packages/flask/app.py:1560]
Traceback (most recent call last):
  File "/anaconda3/lib/python3.6/site-packages/flask/app.py", line 1982, in wsgi_app
    response = self.full_dispatch_request()
  File "/anaconda3/lib/python3.6/site-packages/flask/app.py", line 1615, in full_dispatch_request
    return self.finalize_request(rv)
  File "/anaconda3/lib/python3.6/site-packages/flask/app.py", line 1630, in finalize_request
    response = self.make_response(rv)
  File "/anaconda3/lib/python3.6/site-packages/flask/app.py", line 1725, in make_response
    raise ValueError('View function did not return a response')
ValueError: View function did not return a response
2018-05-07 15:19:52,121 ERROR:             Exception on /favicon.ico [GET] [in /anaconda3/lib/python3.6/site-packages/flask/app.py:1560]
Traceback (most recent call last):
  File "/anaconda3/lib/python3.6/site-packages/flask/app.py", line 1982, in wsgi_app
    response = self.full_dispatch_request()
  File "/anaconda3/lib/python3.6/site-packages/flask/app.py", line 1615, in full_dispatch_request
    return self.finalize_request(rv)
  File "/anaconda3/lib/python3.6/site-packages/flask/app.py", line 1630, in finalize_request
    response = self.make_response(rv)
  File "/anaconda3/lib/python3.6/site-packages/flask/app.py", line 1725, in make_response
    raise ValueError('View function did not return a response')
ValueError: View function did not return a response
2018-05-07 15:20:39,930 ERROR:             Exception on /favicon.ico [GET] [in /anaconda3/lib/python3.6/site-packages/flask/app.py:1560]
Traceback (most recent call last):
  File "/anaconda3/lib/python3.6/site-packages/flask/app.py", line 1982, in wsgi_app
    response = self.full_dispatch_request()
  File "/anaconda3/lib/python3.6/site-packages/flask/app.py", line 1615, in full_dispatch_request
    return self.finalize_request(rv)
  File "/anaconda3/lib/python3.6/site-packages/flask/app.py", line 1630, in finalize_request
    response = self.make_response(rv)
  File "/anaconda3/lib/python3.6/site-packages/flask/app.py", line 1725, in make_response
    raise ValueError('View function did not return a response')
ValueError: View function did not return a response
2018-05-07 15:21:11,354 ERROR:             Exception on /favicon.ico [GET] [in /anaconda3/lib/python3.6/site-packages/flask/app.py:1560]
Traceback (most recent call last):
  File "/anaconda3/lib/python3.6/site-packages/flask/app.py", line 1982, in wsgi_app
    response = self.full_dispatch_request()
  File "/anaconda3/lib/python3.6/site-packages/flask/app.py", line 1615, in full_dispatch_request
    return self.finalize_request(rv)
  File "/anaconda3/lib/python3.6/site-packages/flask/app.py", line 1630, in finalize_request
    response = self.make_response(rv)
  File "/anaconda3/lib/python3.6/site-packages/flask/app.py", line 1725, in make_response
    raise ValueError('View function did not return a response')
ValueError: View function did not return a response
2018-05-07 15:25:47,296 ERROR:             Exception on /favicon.ico [GET] [in /anaconda3/lib/python3.6/site-packages/flask/app.py:1560]
Traceback (most recent call last):
  File "/anaconda3/lib/python3.6/site-packages/flask/app.py", line 1982, in wsgi_app
    response = self.full_dispatch_request()
  File "/anaconda3/lib/python3.6/site-packages/flask/app.py", line 1615, in full_dispatch_request
    return self.finalize_request(rv)
  File "/anaconda3/lib/python3.6/site-packages/flask/app.py", line 1630, in finalize_request
    response = self.make_response(rv)
  File "/anaconda3/lib/python3.6/site-packages/flask/app.py", line 1725, in make_response
    raise ValueError('View function did not return a response')
ValueError: View function did not return a response
2018-05-07 15:26:47,182 INFO:             errors [in app.py:58]
2018-05-07 15:26:54,565 ERROR:             Exception on /favicon.ico [GET] [in /anaconda3/lib/python3.6/site-packages/flask/app.py:1560]
Traceback (most recent call last):
  File "/anaconda3/lib/python3.6/site-packages/flask/app.py", line 1982, in wsgi_app
    response = self.full_dispatch_request()
  File "/anaconda3/lib/python3.6/site-packages/flask/app.py", line 1615, in full_dispatch_request
    return self.finalize_request(rv)
  File "/anaconda3/lib/python3.6/site-packages/flask/app.py", line 1630, in finalize_request
    response = self.make_response(rv)
  File "/anaconda3/lib/python3.6/site-packages/flask/app.py", line 1725, in make_response
    raise ValueError('View function did not return a response')
ValueError: View function did not return a response
2018-05-07 15:28:13,604 INFO:             errors [in app.py:58]
2018-05-07 15:28:20,235 ERROR:             Exception on /favicon.ico [GET] [in /anaconda3/lib/python3.6/site-packages/flask/app.py:1560]
Traceback (most recent call last):
  File "/anaconda3/lib/python3.6/site-packages/flask/app.py", line 1982, in wsgi_app
    response = self.full_dispatch_request()
  File "/anaconda3/lib/python3.6/site-packages/flask/app.py", line 1615, in full_dispatch_request
    return self.finalize_request(rv)
  File "/anaconda3/lib/python3.6/site-packages/flask/app.py", line 1630, in finalize_request
    response = self.make_response(rv)
  File "/anaconda3/lib/python3.6/site-packages/flask/app.py", line 1725, in make_response
    raise ValueError('View function did not return a response')
ValueError: View function did not return a response
2018-05-07 15:30:38,397 INFO:             errors [in app.py:67]
2018-05-07 15:30:43,544 ERROR:             Exception on /favicon.ico [GET] [in /anaconda3/lib/python3.6/site-packages/flask/app.py:1560]
Traceback (most recent call last):
  File "/anaconda3/lib/python3.6/site-packages/flask/app.py", line 1982, in wsgi_app
    response = self.full_dispatch_request()
  File "/anaconda3/lib/python3.6/site-packages/flask/app.py", line 1615, in full_dispatch_request
    return self.finalize_request(rv)
  File "/anaconda3/lib/python3.6/site-packages/flask/app.py", line 1630, in finalize_request
    response = self.make_response(rv)
  File "/anaconda3/lib/python3.6/site-packages/flask/app.py", line 1725, in make_response
    raise ValueError('View function did not return a response')
ValueError: View function did not return a response
2018-05-07 15:33:54,135 INFO:             errors [in app.py:69]
2018-05-07 15:34:00,170 ERROR:             Exception on /favicon.ico [GET] [in /anaconda3/lib/python3.6/site-packages/flask/app.py:1560]
Traceback (most recent call last):
  File "/anaconda3/lib/python3.6/site-packages/flask/app.py", line 1982, in wsgi_app
    response = self.full_dispatch_request()
  File "/anaconda3/lib/python3.6/site-packages/flask/app.py", line 1615, in full_dispatch_request
    return self.finalize_request(rv)
  File "/anaconda3/lib/python3.6/site-packages/flask/app.py", line 1630, in finalize_request
    response = self.make_response(rv)
  File "/anaconda3/lib/python3.6/site-packages/flask/app.py", line 1725, in make_response
    raise ValueError('View function did not return a response')
ValueError: View function did not return a response
2018-05-07 15:34:06,601 ERROR:             Exception on /v1/ocr [POST] [in /anaconda3/lib/python3.6/site-packages/flask/app.py:1560]
Traceback (most recent call last):
  File "/anaconda3/lib/python3.6/site-packages/flask/app.py", line 1982, in wsgi_app
    response = self.full_dispatch_request()
  File "/anaconda3/lib/python3.6/site-packages/flask/app.py", line 1615, in full_dispatch_request
    return self.finalize_request(rv)
  File "/anaconda3/lib/python3.6/site-packages/flask/app.py", line 1630, in finalize_request
    response = self.make_response(rv)
  File "/anaconda3/lib/python3.6/site-packages/flask/app.py", line 1740, in make_response
    rv = self.response_class.force_type(rv, request.environ)
  File "/anaconda3/lib/python3.6/site-packages/werkzeug/wrappers.py", line 921, in force_type
    response = BaseResponse(*_run_wsgi_app(response, environ))
  File "/anaconda3/lib/python3.6/site-packages/werkzeug/wrappers.py", line 59, in _run_wsgi_app
    return _run_wsgi_app(*args)
  File "/anaconda3/lib/python3.6/site-packages/werkzeug/test.py", line 923, in run_wsgi_app
    app_rv = app(environ, start_response)
TypeError: 'dict' object is not callable
2018-05-07 15:36:34,361 INFO:             errors [in app.py:69]
2018-05-07 15:36:43,580 ERROR:             Exception on /favicon.ico [GET] [in /anaconda3/lib/python3.6/site-packages/flask/app.py:1560]
Traceback (most recent call last):
  File "/anaconda3/lib/python3.6/site-packages/flask/app.py", line 1982, in wsgi_app
    response = self.full_dispatch_request()
  File "/anaconda3/lib/python3.6/site-packages/flask/app.py", line 1615, in full_dispatch_request
    return self.finalize_request(rv)
  File "/anaconda3/lib/python3.6/site-packages/flask/app.py", line 1630, in finalize_request
    response = self.make_response(rv)
  File "/anaconda3/lib/python3.6/site-packages/flask/app.py", line 1725, in make_response
    raise ValueError('View function did not return a response')
ValueError: View function did not return a response
2018-05-07 15:36:50,046 ERROR:             Exception on /v1/ocr [POST] [in /anaconda3/lib/python3.6/site-packages/flask/app.py:1560]
Traceback (most recent call last):
  File "/anaconda3/lib/python3.6/site-packages/flask/app.py", line 1982, in wsgi_app
    response = self.full_dispatch_request()
  File "/anaconda3/lib/python3.6/site-packages/flask/app.py", line 1615, in full_dispatch_request
    return self.finalize_request(rv)
  File "/anaconda3/lib/python3.6/site-packages/flask/app.py", line 1630, in finalize_request
    response = self.make_response(rv)
  File "/anaconda3/lib/python3.6/site-packages/flask/app.py", line 1740, in make_response
    rv = self.response_class.force_type(rv, request.environ)
  File "/anaconda3/lib/python3.6/site-packages/werkzeug/wrappers.py", line 921, in force_type
    response = BaseResponse(*_run_wsgi_app(response, environ))
  File "/anaconda3/lib/python3.6/site-packages/werkzeug/wrappers.py", line 59, in _run_wsgi_app
    return _run_wsgi_app(*args)
  File "/anaconda3/lib/python3.6/site-packages/werkzeug/test.py", line 923, in run_wsgi_app
    app_rv = app(environ, start_response)
TypeError: 'dict' object is not callable
2018-05-07 15:38:58,978 INFO:             errors [in app.py:69]
2018-05-07 15:39:05,164 ERROR:             Exception on /favicon.ico [GET] [in /anaconda3/lib/python3.6/site-packages/flask/app.py:1560]
Traceback (most recent call last):
  File "/anaconda3/lib/python3.6/site-packages/flask/app.py", line 1982, in wsgi_app
    response = self.full_dispatch_request()
  File "/anaconda3/lib/python3.6/site-packages/flask/app.py", line 1615, in full_dispatch_request
    return self.finalize_request(rv)
  File "/anaconda3/lib/python3.6/site-packages/flask/app.py", line 1630, in finalize_request
    response = self.make_response(rv)
  File "/anaconda3/lib/python3.6/site-packages/flask/app.py", line 1725, in make_response
    raise ValueError('View function did not return a response')
ValueError: View function did not return a response
2018-05-07 15:41:21,580 ERROR:             Exception on /favicon.ico [GET] [in /anaconda3/lib/python3.6/site-packages/flask/app.py:1560]
Traceback (most recent call last):
  File "/anaconda3/lib/python3.6/site-packages/flask/app.py", line 1982, in wsgi_app
    response = self.full_dispatch_request()
  File "/anaconda3/lib/python3.6/site-packages/flask/app.py", line 1615, in full_dispatch_request
    return self.finalize_request(rv)
  File "/anaconda3/lib/python3.6/site-packages/flask/app.py", line 1630, in finalize_request
    response = self.make_response(rv)
  File "/anaconda3/lib/python3.6/site-packages/flask/app.py", line 1725, in make_response
    raise ValueError('View function did not return a response')
ValueError: View function did not return a response
2018-05-07 15:42:36,029 INFO:             errors [in app.py:69]
2018-05-07 15:42:49,363 ERROR:             Exception on /favicon.ico [GET] [in /anaconda3/lib/python3.6/site-packages/flask/app.py:1560]
Traceback (most recent call last):
  File "/anaconda3/lib/python3.6/site-packages/flask/app.py", line 1982, in wsgi_app
    response = self.full_dispatch_request()
  File "/anaconda3/lib/python3.6/site-packages/flask/app.py", line 1615, in full_dispatch_request
    return self.finalize_request(rv)
  File "/anaconda3/lib/python3.6/site-packages/flask/app.py", line 1630, in finalize_request
    response = self.make_response(rv)
  File "/anaconda3/lib/python3.6/site-packages/flask/app.py", line 1725, in make_response
    raise ValueError('View function did not return a response')
ValueError: View function did not return a response
2018-05-07 15:46:09,580 ERROR:             Exception on /favicon.ico [GET] [in /anaconda3/lib/python3.6/site-packages/flask/app.py:1560]
Traceback (most recent call last):
  File "/anaconda3/lib/python3.6/site-packages/flask/app.py", line 1982, in wsgi_app
    response = self.full_dispatch_request()
  File "/anaconda3/lib/python3.6/site-packages/flask/app.py", line 1615, in full_dispatch_request
    return self.finalize_request(rv)
  File "/anaconda3/lib/python3.6/site-packages/flask/app.py", line 1630, in finalize_request
    response = self.make_response(rv)
  File "/anaconda3/lib/python3.6/site-packages/flask/app.py", line 1725, in make_response
    raise ValueError('View function did not return a response')
ValueError: View function did not return a response
2018-05-07 15:48:49,497 ERROR:             Exception on /favicon.ico [GET] [in /anaconda3/lib/python3.6/site-packages/flask/app.py:1560]
Traceback (most recent call last):
  File "/anaconda3/lib/python3.6/site-packages/flask/app.py", line 1982, in wsgi_app
    response = self.full_dispatch_request()
  File "/anaconda3/lib/python3.6/site-packages/flask/app.py", line 1615, in full_dispatch_request
    return self.finalize_request(rv)
  File "/anaconda3/lib/python3.6/site-packages/flask/app.py", line 1630, in finalize_request
    response = self.make_response(rv)
  File "/anaconda3/lib/python3.6/site-packages/flask/app.py", line 1725, in make_response
    raise ValueError('View function did not return a response')
ValueError: View function did not return a response
2018-05-07 15:50:59,940 ERROR:             Exception on /favicon.ico [GET] [in /anaconda3/lib/python3.6/site-packages/flask/app.py:1560]
Traceback (most recent call last):
  File "/anaconda3/lib/python3.6/site-packages/flask/app.py", line 1982, in wsgi_app
    response = self.full_dispatch_request()
  File "/anaconda3/lib/python3.6/site-packages/flask/app.py", line 1615, in full_dispatch_request
    return self.finalize_request(rv)
  File "/anaconda3/lib/python3.6/site-packages/flask/app.py", line 1630, in finalize_request
    response = self.make_response(rv)
  File "/anaconda3/lib/python3.6/site-packages/flask/app.py", line 1725, in make_response
    raise ValueError('View function did not return a response')
ValueError: View function did not return a response
2018-05-07 15:51:08,408 ERROR:             Exception on /favicon.ico [GET] [in /anaconda3/lib/python3.6/site-packages/flask/app.py:1560]
Traceback (most recent call last):
  File "/anaconda3/lib/python3.6/site-packages/flask/app.py", line 1982, in wsgi_app
    response = self.full_dispatch_request()
  File "/anaconda3/lib/python3.6/site-packages/flask/app.py", line 1615, in full_dispatch_request
    return self.finalize_request(rv)
  File "/anaconda3/lib/python3.6/site-packages/flask/app.py", line 1630, in finalize_request
    response = self.make_response(rv)
  File "/anaconda3/lib/python3.6/site-packages/flask/app.py", line 1725, in make_response
    raise ValueError('View function did not return a response')
ValueError: View function did not return a response
2018-05-07 15:51:37,313 ERROR:             Exception on /favicon.ico [GET] [in /anaconda3/lib/python3.6/site-packages/flask/app.py:1560]
Traceback (most recent call last):
  File "/anaconda3/lib/python3.6/site-packages/flask/app.py", line 1982, in wsgi_app
    response = self.full_dispatch_request()
  File "/anaconda3/lib/python3.6/site-packages/flask/app.py", line 1615, in full_dispatch_request
    return self.finalize_request(rv)
  File "/anaconda3/lib/python3.6/site-packages/flask/app.py", line 1630, in finalize_request
    response = self.make_response(rv)
  File "/anaconda3/lib/python3.6/site-packages/flask/app.py", line 1725, in make_response
    raise ValueError('View function did not return a response')
ValueError: View function did not return a response
2018-05-07 15:52:38,179 ERROR:             Exception on /favicon.ico [GET] [in /anaconda3/lib/python3.6/site-packages/flask/app.py:1560]
Traceback (most recent call last):
  File "/anaconda3/lib/python3.6/site-packages/flask/app.py", line 1982, in wsgi_app
    response = self.full_dispatch_request()
  File "/anaconda3/lib/python3.6/site-packages/flask/app.py", line 1615, in full_dispatch_request
    return self.finalize_request(rv)
  File "/anaconda3/lib/python3.6/site-packages/flask/app.py", line 1630, in finalize_request
    response = self.make_response(rv)
  File "/anaconda3/lib/python3.6/site-packages/flask/app.py", line 1725, in make_response
    raise ValueError('View function did not return a response')
ValueError: View function did not return a response
2018-05-07 15:53:18,319 ERROR:             Exception on /favicon.ico [GET] [in /anaconda3/lib/python3.6/site-packages/flask/app.py:1560]
Traceback (most recent call last):
  File "/anaconda3/lib/python3.6/site-packages/flask/app.py", line 1982, in wsgi_app
    response = self.full_dispatch_request()
  File "/anaconda3/lib/python3.6/site-packages/flask/app.py", line 1615, in full_dispatch_request
    return self.finalize_request(rv)
  File "/anaconda3/lib/python3.6/site-packages/flask/app.py", line 1630, in finalize_request
    response = self.make_response(rv)
  File "/anaconda3/lib/python3.6/site-packages/flask/app.py", line 1725, in make_response
    raise ValueError('View function did not return a response')
ValueError: View function did not return a response
2018-05-07 15:55:32,550 INFO:             errors [in app.py:69]
2018-05-07 15:55:40,253 ERROR:             Exception on /favicon.ico [GET] [in /anaconda3/lib/python3.6/site-packages/flask/app.py:1560]
Traceback (most recent call last):
  File "/anaconda3/lib/python3.6/site-packages/flask/app.py", line 1982, in wsgi_app
    response = self.full_dispatch_request()
  File "/anaconda3/lib/python3.6/site-packages/flask/app.py", line 1615, in full_dispatch_request
    return self.finalize_request(rv)
  File "/anaconda3/lib/python3.6/site-packages/flask/app.py", line 1630, in finalize_request
    response = self.make_response(rv)
  File "/anaconda3/lib/python3.6/site-packages/flask/app.py", line 1725, in make_response
    raise ValueError('View function did not return a response')
ValueError: View function did not return a response
2018-05-07 16:50:11,877 ERROR:             Exception on /favicon.ico [GET] [in /anaconda3/lib/python3.6/site-packages/flask/app.py:1560]
Traceback (most recent call last):
  File "/anaconda3/lib/python3.6/site-packages/flask/app.py", line 1982, in wsgi_app
    response = self.full_dispatch_request()
  File "/anaconda3/lib/python3.6/site-packages/flask/app.py", line 1615, in full_dispatch_request
    return self.finalize_request(rv)
  File "/anaconda3/lib/python3.6/site-packages/flask/app.py", line 1630, in finalize_request
    response = self.make_response(rv)
  File "/anaconda3/lib/python3.6/site-packages/flask/app.py", line 1725, in make_response
    raise ValueError('View function did not return a response')
ValueError: View function did not return a response
2018-05-07 16:50:21,657 ERROR:             Exception on /favicon.ico [GET] [in /anaconda3/lib/python3.6/site-packages/flask/app.py:1560]
Traceback (most recent call last):
  File "/anaconda3/lib/python3.6/site-packages/flask/app.py", line 1982, in wsgi_app
    response = self.full_dispatch_request()
  File "/anaconda3/lib/python3.6/site-packages/flask/app.py", line 1615, in full_dispatch_request
    return self.finalize_request(rv)
  File "/anaconda3/lib/python3.6/site-packages/flask/app.py", line 1630, in finalize_request
    response = self.make_response(rv)
  File "/anaconda3/lib/python3.6/site-packages/flask/app.py", line 1725, in make_response
    raise ValueError('View function did not return a response')
ValueError: View function did not return a response
2018-05-07 16:50:51,874 ERROR:             Exception on /favicon.ico [GET] [in /anaconda3/lib/python3.6/site-packages/flask/app.py:1560]
Traceback (most recent call last):
  File "/anaconda3/lib/python3.6/site-packages/flask/app.py", line 1982, in wsgi_app
    response = self.full_dispatch_request()
  File "/anaconda3/lib/python3.6/site-packages/flask/app.py", line 1615, in full_dispatch_request
    return self.finalize_request(rv)
  File "/anaconda3/lib/python3.6/site-packages/flask/app.py", line 1630, in finalize_request
    response = self.make_response(rv)
  File "/anaconda3/lib/python3.6/site-packages/flask/app.py", line 1725, in make_response
    raise ValueError('View function did not return a response')
ValueError: View function did not return a response
2018-05-07 16:53:22,765 ERROR:             Exception on /favicon.ico [GET] [in /anaconda3/lib/python3.6/site-packages/flask/app.py:1560]
Traceback (most recent call last):
  File "/anaconda3/lib/python3.6/site-packages/flask/app.py", line 1982, in wsgi_app
    response = self.full_dispatch_request()
  File "/anaconda3/lib/python3.6/site-packages/flask/app.py", line 1615, in full_dispatch_request
    return self.finalize_request(rv)
  File "/anaconda3/lib/python3.6/site-packages/flask/app.py", line 1630, in finalize_request
    response = self.make_response(rv)
  File "/anaconda3/lib/python3.6/site-packages/flask/app.py", line 1725, in make_response
    raise ValueError('View function did not return a response')
ValueError: View function did not return a response
2018-05-07 16:53:32,708 ERROR:             Exception on /favicon.ico [GET] [in /anaconda3/lib/python3.6/site-packages/flask/app.py:1560]
Traceback (most recent call last):
  File "/anaconda3/lib/python3.6/site-packages/flask/app.py", line 1982, in wsgi_app
    response = self.full_dispatch_request()
  File "/anaconda3/lib/python3.6/site-packages/flask/app.py", line 1615, in full_dispatch_request
    return self.finalize_request(rv)
  File "/anaconda3/lib/python3.6/site-packages/flask/app.py", line 1630, in finalize_request
    response = self.make_response(rv)
  File "/anaconda3/lib/python3.6/site-packages/flask/app.py", line 1725, in make_response
    raise ValueError('View function did not return a response')
ValueError: View function did not return a response
2018-05-07 16:57:01,628 ERROR:             Exception on /favicon.ico [GET] [in /anaconda3/lib/python3.6/site-packages/flask/app.py:1560]
Traceback (most recent call last):
  File "/anaconda3/lib/python3.6/site-packages/flask/app.py", line 1982, in wsgi_app
    response = self.full_dispatch_request()
  File "/anaconda3/lib/python3.6/site-packages/flask/app.py", line 1615, in full_dispatch_request
    return self.finalize_request(rv)
  File "/anaconda3/lib/python3.6/site-packages/flask/app.py", line 1630, in finalize_request
    response = self.make_response(rv)
  File "/anaconda3/lib/python3.6/site-packages/flask/app.py", line 1725, in make_response
    raise ValueError('View function did not return a response')
ValueError: View function did not return a response
2018-05-07 16:58:35,187 ERROR:             Exception on /favicon.ico [GET] [in /anaconda3/lib/python3.6/site-packages/flask/app.py:1560]
Traceback (most recent call last):
  File "/anaconda3/lib/python3.6/site-packages/flask/app.py", line 1982, in wsgi_app
    response = self.full_dispatch_request()
  File "/anaconda3/lib/python3.6/site-packages/flask/app.py", line 1615, in full_dispatch_request
    return self.finalize_request(rv)
  File "/anaconda3/lib/python3.6/site-packages/flask/app.py", line 1630, in finalize_request
    response = self.make_response(rv)
  File "/anaconda3/lib/python3.6/site-packages/flask/app.py", line 1725, in make_response
    raise ValueError('View function did not return a response')
ValueError: View function did not return a response
2018-05-07 17:28:45,080 ERROR:             Exception on /users/piusraj/documents/python_files/sample2.jpg [GET] [in /anaconda3/lib/python3.6/site-packages/flask/app.py:1560]
Traceback (most recent call last):
  File "/anaconda3/lib/python3.6/site-packages/flask/app.py", line 1982, in wsgi_app
    response = self.full_dispatch_request()
  File "/anaconda3/lib/python3.6/site-packages/flask/app.py", line 1615, in full_dispatch_request
    return self.finalize_request(rv)
  File "/anaconda3/lib/python3.6/site-packages/flask/app.py", line 1630, in finalize_request
    response = self.make_response(rv)
  File "/anaconda3/lib/python3.6/site-packages/flask/app.py", line 1725, in make_response
    raise ValueError('View function did not return a response')
ValueError: View function did not return a response
2018-05-07 17:28:50,456 ERROR:             Exception on /favicon.ico [GET] [in /anaconda3/lib/python3.6/site-packages/flask/app.py:1560]
Traceback (most recent call last):
  File "/anaconda3/lib/python3.6/site-packages/flask/app.py", line 1982, in wsgi_app
    response = self.full_dispatch_request()
  File "/anaconda3/lib/python3.6/site-packages/flask/app.py", line 1615, in full_dispatch_request
    return self.finalize_request(rv)
  File "/anaconda3/lib/python3.6/site-packages/flask/app.py", line 1630, in finalize_request
    response = self.make_response(rv)
  File "/anaconda3/lib/python3.6/site-packages/flask/app.py", line 1725, in make_response
    raise ValueError('View function did not return a response')
ValueError: View function did not return a response
2018-05-07 17:29:10,009 ERROR:             Exception on /favicon.ico [GET] [in /anaconda3/lib/python3.6/site-packages/flask/app.py:1560]
Traceback (most recent call last):
  File "/anaconda3/lib/python3.6/site-packages/flask/app.py", line 1982, in wsgi_app
    response = self.full_dispatch_request()
  File "/anaconda3/lib/python3.6/site-packages/flask/app.py", line 1615, in full_dispatch_request
    return self.finalize_request(rv)
  File "/anaconda3/lib/python3.6/site-packages/flask/app.py", line 1630, in finalize_request
    response = self.make_response(rv)
  File "/anaconda3/lib/python3.6/site-packages/flask/app.py", line 1725, in make_response
    raise ValueError('View function did not return a response')
ValueError: View function did not return a response
2018-05-07 17:34:15,835 INFO:             errors [in app.py:69]
2018-05-07 17:34:23,978 ERROR:             Exception on /favicon.ico [GET] [in /anaconda3/lib/python3.6/site-packages/flask/app.py:1560]
Traceback (most recent call last):
  File "/anaconda3/lib/python3.6/site-packages/flask/app.py", line 1982, in wsgi_app
    response = self.full_dispatch_request()
  File "/anaconda3/lib/python3.6/site-packages/flask/app.py", line 1615, in full_dispatch_request
    return self.finalize_request(rv)
  File "/anaconda3/lib/python3.6/site-packages/flask/app.py", line 1630, in finalize_request
    response = self.make_response(rv)
  File "/anaconda3/lib/python3.6/site-packages/flask/app.py", line 1725, in make_response
    raise ValueError('View function did not return a response')
ValueError: View function did not return a response
2018-05-07 17:34:37,460 ERROR:             Exception on /favicon.ico [GET] [in /anaconda3/lib/python3.6/site-packages/flask/app.py:1560]
Traceback (most recent call last):
  File "/anaconda3/lib/python3.6/site-packages/flask/app.py", line 1982, in wsgi_app
    response = self.full_dispatch_request()
  File "/anaconda3/lib/python3.6/site-packages/flask/app.py", line 1615, in full_dispatch_request
    return self.finalize_request(rv)
  File "/anaconda3/lib/python3.6/site-packages/flask/app.py", line 1630, in finalize_request
    response = self.make_response(rv)
  File "/anaconda3/lib/python3.6/site-packages/flask/app.py", line 1725, in make_response
    raise ValueError('View function did not return a response')
ValueError: View function did not return a response
2018-05-07 17:35:36,352 ERROR:             Exception on /favicon.ico [GET] [in /anaconda3/lib/python3.6/site-packages/flask/app.py:1560]
Traceback (most recent call last):
  File "/anaconda3/lib/python3.6/site-packages/flask/app.py", line 1982, in wsgi_app
    response = self.full_dispatch_request()
  File "/anaconda3/lib/python3.6/site-packages/flask/app.py", line 1615, in full_dispatch_request
    return self.finalize_request(rv)
  File "/anaconda3/lib/python3.6/site-packages/flask/app.py", line 1630, in finalize_request
    response = self.make_response(rv)
  File "/anaconda3/lib/python3.6/site-packages/flask/app.py", line 1725, in make_response
    raise ValueError('View function did not return a response')
ValueError: View function did not return a response
2018-05-07 17:35:42,918 ERROR:             Exception on /users/piusraj/documents/python_files/sample2.jpg [GET] [in /anaconda3/lib/python3.6/site-packages/flask/app.py:1560]
Traceback (most recent call last):
  File "/anaconda3/lib/python3.6/site-packages/flask/app.py", line 1982, in wsgi_app
    response = self.full_dispatch_request()
  File "/anaconda3/lib/python3.6/site-packages/flask/app.py", line 1615, in full_dispatch_request
    return self.finalize_request(rv)
  File "/anaconda3/lib/python3.6/site-packages/flask/app.py", line 1630, in finalize_request
    response = self.make_response(rv)
  File "/anaconda3/lib/python3.6/site-packages/flask/app.py", line 1725, in make_response
    raise ValueError('View function did not return a response')
ValueError: View function did not return a response
2018-05-07 17:35:53,167 ERROR:             Exception on /favicon.ico [GET] [in /anaconda3/lib/python3.6/site-packages/flask/app.py:1560]
Traceback (most recent call last):
  File "/anaconda3/lib/python3.6/site-packages/flask/app.py", line 1982, in wsgi_app
    response = self.full_dispatch_request()
  File "/anaconda3/lib/python3.6/site-packages/flask/app.py", line 1615, in full_dispatch_request
    return self.finalize_request(rv)
  File "/anaconda3/lib/python3.6/site-packages/flask/app.py", line 1630, in finalize_request
    response = self.make_response(rv)
  File "/anaconda3/lib/python3.6/site-packages/flask/app.py", line 1725, in make_response
    raise ValueError('View function did not return a response')
ValueError: View function did not return a response
2018-05-07 17:36:43,788 ERROR:             Exception on /users/piusraj/documents/python_files/sample5.jpg [GET] [in /anaconda3/lib/python3.6/site-packages/flask/app.py:1560]
Traceback (most recent call last):
  File "/anaconda3/lib/python3.6/site-packages/flask/app.py", line 1982, in wsgi_app
    response = self.full_dispatch_request()
  File "/anaconda3/lib/python3.6/site-packages/flask/app.py", line 1615, in full_dispatch_request
    return self.finalize_request(rv)
  File "/anaconda3/lib/python3.6/site-packages/flask/app.py", line 1630, in finalize_request
    response = self.make_response(rv)
  File "/anaconda3/lib/python3.6/site-packages/flask/app.py", line 1725, in make_response
    raise ValueError('View function did not return a response')
ValueError: View function did not return a response
2018-05-07 17:38:20,927 ERROR:             Exception on /favicon.ico [GET] [in /anaconda3/lib/python3.6/site-packages/flask/app.py:1560]
Traceback (most recent call last):
  File "/anaconda3/lib/python3.6/site-packages/flask/app.py", line 1982, in wsgi_app
    response = self.full_dispatch_request()
  File "/anaconda3/lib/python3.6/site-packages/flask/app.py", line 1615, in full_dispatch_request
    return self.finalize_request(rv)
  File "/anaconda3/lib/python3.6/site-packages/flask/app.py", line 1630, in finalize_request
    response = self.make_response(rv)
  File "/anaconda3/lib/python3.6/site-packages/flask/app.py", line 1725, in make_response
    raise ValueError('View function did not return a response')
ValueError: View function did not return a response
2018-05-07 17:38:41,732 ERROR:             Exception on /users/piusraj/documents/python_files/sample8.jpg [GET] [in /anaconda3/lib/python3.6/site-packages/flask/app.py:1560]
Traceback (most recent call last):
  File "/anaconda3/lib/python3.6/site-packages/flask/app.py", line 1982, in wsgi_app
    response = self.full_dispatch_request()
  File "/anaconda3/lib/python3.6/site-packages/flask/app.py", line 1615, in full_dispatch_request
    return self.finalize_request(rv)
  File "/anaconda3/lib/python3.6/site-packages/flask/app.py", line 1630, in finalize_request
    response = self.make_response(rv)
  File "/anaconda3/lib/python3.6/site-packages/flask/app.py", line 1725, in make_response
    raise ValueError('View function did not return a response')
ValueError: View function did not return a response
2018-05-07 17:40:07,778 ERROR:             Exception on /favicon.ico [GET] [in /anaconda3/lib/python3.6/site-packages/flask/app.py:1560]
Traceback (most recent call last):
  File "/anaconda3/lib/python3.6/site-packages/flask/app.py", line 1982, in wsgi_app
    response = self.full_dispatch_request()
  File "/anaconda3/lib/python3.6/site-packages/flask/app.py", line 1615, in full_dispatch_request
    return self.finalize_request(rv)
  File "/anaconda3/lib/python3.6/site-packages/flask/app.py", line 1630, in finalize_request
    response = self.make_response(rv)
  File "/anaconda3/lib/python3.6/site-packages/flask/app.py", line 1725, in make_response
    raise ValueError('View function did not return a response')
ValueError: View function did not return a response
2018-05-07 17:40:13,365 ERROR:             Exception on /favicon.ico [GET] [in /anaconda3/lib/python3.6/site-packages/flask/app.py:1560]
Traceback (most recent call last):
  File "/anaconda3/lib/python3.6/site-packages/flask/app.py", line 1982, in wsgi_app
    response = self.full_dispatch_request()
  File "/anaconda3/lib/python3.6/site-packages/flask/app.py", line 1615, in full_dispatch_request
    return self.finalize_request(rv)
  File "/anaconda3/lib/python3.6/site-packages/flask/app.py", line 1630, in finalize_request
    response = self.make_response(rv)
  File "/anaconda3/lib/python3.6/site-packages/flask/app.py", line 1725, in make_response
    raise ValueError('View function did not return a response')
ValueError: View function did not return a response
2018-05-07 17:40:17,634 ERROR:             Exception on /favicon.ico [GET] [in /anaconda3/lib/python3.6/site-packages/flask/app.py:1560]
Traceback (most recent call last):
  File "/anaconda3/lib/python3.6/site-packages/flask/app.py", line 1982, in wsgi_app
    response = self.full_dispatch_request()
  File "/anaconda3/lib/python3.6/site-packages/flask/app.py", line 1615, in full_dispatch_request
    return self.finalize_request(rv)
  File "/anaconda3/lib/python3.6/site-packages/flask/app.py", line 1630, in finalize_request
    response = self.make_response(rv)
  File "/anaconda3/lib/python3.6/site-packages/flask/app.py", line 1725, in make_response
    raise ValueError('View function did not return a response')
ValueError: View function did not return a response
2018-05-07 17:40:23,080 ERROR:             Exception on /favicon.ico [GET] [in /anaconda3/lib/python3.6/site-packages/flask/app.py:1560]
Traceback (most recent call last):
  File "/anaconda3/lib/python3.6/site-packages/flask/app.py", line 1982, in wsgi_app
    response = self.full_dispatch_request()
  File "/anaconda3/lib/python3.6/site-packages/flask/app.py", line 1615, in full_dispatch_request
    return self.finalize_request(rv)
  File "/anaconda3/lib/python3.6/site-packages/flask/app.py", line 1630, in finalize_request
    response = self.make_response(rv)
  File "/anaconda3/lib/python3.6/site-packages/flask/app.py", line 1725, in make_response
    raise ValueError('View function did not return a response')
ValueError: View function did not return a response
2018-05-07 17:40:35,988 ERROR:             Exception on /favicon.ico [GET] [in /anaconda3/lib/python3.6/site-packages/flask/app.py:1560]
Traceback (most recent call last):
  File "/anaconda3/lib/python3.6/site-packages/flask/app.py", line 1982, in wsgi_app
    response = self.full_dispatch_request()
  File "/anaconda3/lib/python3.6/site-packages/flask/app.py", line 1615, in full_dispatch_request
    return self.finalize_request(rv)
  File "/anaconda3/lib/python3.6/site-packages/flask/app.py", line 1630, in finalize_request
    response = self.make_response(rv)
  File "/anaconda3/lib/python3.6/site-packages/flask/app.py", line 1725, in make_response
    raise ValueError('View function did not return a response')
ValueError: View function did not return a response
2018-05-07 17:40:41,347 ERROR:             Exception on /users/piusraj/documents/python_files/sample2.jpg [GET] [in /anaconda3/lib/python3.6/site-packages/flask/app.py:1560]
Traceback (most recent call last):
  File "/anaconda3/lib/python3.6/site-packages/flask/app.py", line 1982, in wsgi_app
    response = self.full_dispatch_request()
  File "/anaconda3/lib/python3.6/site-packages/flask/app.py", line 1615, in full_dispatch_request
    return self.finalize_request(rv)
  File "/anaconda3/lib/python3.6/site-packages/flask/app.py", line 1630, in finalize_request
    response = self.make_response(rv)
  File "/anaconda3/lib/python3.6/site-packages/flask/app.py", line 1725, in make_response
    raise ValueError('View function did not return a response')
ValueError: View function did not return a response
2018-05-07 17:44:18,926 INFO:             errors [in app.py:86]
2018-05-07 17:44:24,143 ERROR:             Exception on /favicon.ico [GET] [in /anaconda3/lib/python3.6/site-packages/flask/app.py:1560]
Traceback (most recent call last):
  File "/anaconda3/lib/python3.6/site-packages/flask/app.py", line 1982, in wsgi_app
    response = self.full_dispatch_request()
  File "/anaconda3/lib/python3.6/site-packages/flask/app.py", line 1615, in full_dispatch_request
    return self.finalize_request(rv)
  File "/anaconda3/lib/python3.6/site-packages/flask/app.py", line 1630, in finalize_request
    response = self.make_response(rv)
  File "/anaconda3/lib/python3.6/site-packages/flask/app.py", line 1725, in make_response
    raise ValueError('View function did not return a response')
ValueError: View function did not return a response
2018-05-07 17:44:29,459 ERROR:             Exception on /users/piusraj/documents/python_files/sample2.jpg [GET] [in /anaconda3/lib/python3.6/site-packages/flask/app.py:1560]
Traceback (most recent call last):
  File "/anaconda3/lib/python3.6/site-packages/flask/app.py", line 1982, in wsgi_app
    response = self.full_dispatch_request()
  File "/anaconda3/lib/python3.6/site-packages/flask/app.py", line 1615, in full_dispatch_request
    return self.finalize_request(rv)
  File "/anaconda3/lib/python3.6/site-packages/flask/app.py", line 1630, in finalize_request
    response = self.make_response(rv)
  File "/anaconda3/lib/python3.6/site-packages/flask/app.py", line 1725, in make_response
    raise ValueError('View function did not return a response')
ValueError: View function did not return a response
2018-05-07 17:44:31,838 ERROR:             Exception on /favicon.ico [GET] [in /anaconda3/lib/python3.6/site-packages/flask/app.py:1560]
Traceback (most recent call last):
  File "/anaconda3/lib/python3.6/site-packages/flask/app.py", line 1982, in wsgi_app
    response = self.full_dispatch_request()
  File "/anaconda3/lib/python3.6/site-packages/flask/app.py", line 1615, in full_dispatch_request
    return self.finalize_request(rv)
  File "/anaconda3/lib/python3.6/site-packages/flask/app.py", line 1630, in finalize_request
    response = self.make_response(rv)
  File "/anaconda3/lib/python3.6/site-packages/flask/app.py", line 1725, in make_response
    raise ValueError('View function did not return a response')
ValueError: View function did not return a response
2018-05-07 17:44:45,331 ERROR:             Exception on /users/piusraj/documents/python_files/sample5.jpg [GET] [in /anaconda3/lib/python3.6/site-packages/flask/app.py:1560]
Traceback (most recent call last):
  File "/anaconda3/lib/python3.6/site-packages/flask/app.py", line 1982, in wsgi_app
    response = self.full_dispatch_request()
  File "/anaconda3/lib/python3.6/site-packages/flask/app.py", line 1615, in full_dispatch_request
    return self.finalize_request(rv)
  File "/anaconda3/lib/python3.6/site-packages/flask/app.py", line 1630, in finalize_request
    response = self.make_response(rv)
  File "/anaconda3/lib/python3.6/site-packages/flask/app.py", line 1725, in make_response
    raise ValueError('View function did not return a response')
ValueError: View function did not return a response
2018-05-07 17:44:52,511 ERROR:             Exception on /favicon.ico [GET] [in /anaconda3/lib/python3.6/site-packages/flask/app.py:1560]
Traceback (most recent call last):
  File "/anaconda3/lib/python3.6/site-packages/flask/app.py", line 1982, in wsgi_app
    response = self.full_dispatch_request()
  File "/anaconda3/lib/python3.6/site-packages/flask/app.py", line 1615, in full_dispatch_request
    return self.finalize_request(rv)
  File "/anaconda3/lib/python3.6/site-packages/flask/app.py", line 1630, in finalize_request
    response = self.make_response(rv)
  File "/anaconda3/lib/python3.6/site-packages/flask/app.py", line 1725, in make_response
    raise ValueError('View function did not return a response')
ValueError: View function did not return a response
2018-05-07 17:46:58,531 INFO:             errors [in app.py:81]
2018-05-07 17:47:02,762 ERROR:             Exception on /favicon.ico [GET] [in /anaconda3/lib/python3.6/site-packages/flask/app.py:1560]
Traceback (most recent call last):
  File "/anaconda3/lib/python3.6/site-packages/flask/app.py", line 1982, in wsgi_app
    response = self.full_dispatch_request()
  File "/anaconda3/lib/python3.6/site-packages/flask/app.py", line 1615, in full_dispatch_request
    return self.finalize_request(rv)
  File "/anaconda3/lib/python3.6/site-packages/flask/app.py", line 1630, in finalize_request
    response = self.make_response(rv)
  File "/anaconda3/lib/python3.6/site-packages/flask/app.py", line 1725, in make_response
    raise ValueError('View function did not return a response')
ValueError: View function did not return a response
2018-05-07 17:50:23,960 INFO:             errors [in app.py:81]
2018-05-07 17:50:32,885 ERROR:             Exception on /favicon.ico [GET] [in /anaconda3/lib/python3.6/site-packages/flask/app.py:1560]
Traceback (most recent call last):
  File "/anaconda3/lib/python3.6/site-packages/flask/app.py", line 1982, in wsgi_app
    response = self.full_dispatch_request()
  File "/anaconda3/lib/python3.6/site-packages/flask/app.py", line 1615, in full_dispatch_request
    return self.finalize_request(rv)
  File "/anaconda3/lib/python3.6/site-packages/flask/app.py", line 1630, in finalize_request
    response = self.make_response(rv)
  File "/anaconda3/lib/python3.6/site-packages/flask/app.py", line 1725, in make_response
    raise ValueError('View function did not return a response')
ValueError: View function did not return a response
2018-05-07 17:50:39,005 ERROR:             Exception on /users/piusraj/documents/python_files/sample2.jpg [GET] [in /anaconda3/lib/python3.6/site-packages/flask/app.py:1560]
Traceback (most recent call last):
  File "/anaconda3/lib/python3.6/site-packages/flask/app.py", line 1982, in wsgi_app
    response = self.full_dispatch_request()
  File "/anaconda3/lib/python3.6/site-packages/flask/app.py", line 1615, in full_dispatch_request
    return self.finalize_request(rv)
  File "/anaconda3/lib/python3.6/site-packages/flask/app.py", line 1630, in finalize_request
    response = self.make_response(rv)
  File "/anaconda3/lib/python3.6/site-packages/flask/app.py", line 1725, in make_response
    raise ValueError('View function did not return a response')
ValueError: View function did not return a response
2018-05-07 17:50:52,413 ERROR:             Exception on /favicon.ico [GET] [in /anaconda3/lib/python3.6/site-packages/flask/app.py:1560]
Traceback (most recent call last):
  File "/anaconda3/lib/python3.6/site-packages/flask/app.py", line 1982, in wsgi_app
    response = self.full_dispatch_request()
  File "/anaconda3/lib/python3.6/site-packages/flask/app.py", line 1615, in full_dispatch_request
    return self.finalize_request(rv)
  File "/anaconda3/lib/python3.6/site-packages/flask/app.py", line 1630, in finalize_request
    response = self.make_response(rv)
  File "/anaconda3/lib/python3.6/site-packages/flask/app.py", line 1725, in make_response
    raise ValueError('View function did not return a response')
ValueError: View function did not return a response
2018-05-07 17:51:42,553 INFO:             errors [in app.py:71]
2018-05-07 17:51:45,938 ERROR:             Exception on /favicon.ico [GET] [in /anaconda3/lib/python3.6/site-packages/flask/app.py:1560]
Traceback (most recent call last):
  File "/anaconda3/lib/python3.6/site-packages/flask/app.py", line 1982, in wsgi_app
    response = self.full_dispatch_request()
  File "/anaconda3/lib/python3.6/site-packages/flask/app.py", line 1615, in full_dispatch_request
    return self.finalize_request(rv)
  File "/anaconda3/lib/python3.6/site-packages/flask/app.py", line 1630, in finalize_request
    response = self.make_response(rv)
  File "/anaconda3/lib/python3.6/site-packages/flask/app.py", line 1725, in make_response
    raise ValueError('View function did not return a response')
ValueError: View function did not return a response
2018-05-07 17:51:50,225 ERROR:             Exception on /users/piusraj/documents/python_files/sample2.jpg [GET] [in /anaconda3/lib/python3.6/site-packages/flask/app.py:1560]
Traceback (most recent call last):
  File "/anaconda3/lib/python3.6/site-packages/flask/app.py", line 1982, in wsgi_app
    response = self.full_dispatch_request()
  File "/anaconda3/lib/python3.6/site-packages/flask/app.py", line 1615, in full_dispatch_request
    return self.finalize_request(rv)
  File "/anaconda3/lib/python3.6/site-packages/flask/app.py", line 1630, in finalize_request
    response = self.make_response(rv)
  File "/anaconda3/lib/python3.6/site-packages/flask/app.py", line 1725, in make_response
    raise ValueError('View function did not return a response')
ValueError: View function did not return a response
2018-05-07 17:51:52,608 ERROR:             Exception on /favicon.ico [GET] [in /anaconda3/lib/python3.6/site-packages/flask/app.py:1560]
Traceback (most recent call last):
  File "/anaconda3/lib/python3.6/site-packages/flask/app.py", line 1982, in wsgi_app
    response = self.full_dispatch_request()
  File "/anaconda3/lib/python3.6/site-packages/flask/app.py", line 1615, in full_dispatch_request
    return self.finalize_request(rv)
  File "/anaconda3/lib/python3.6/site-packages/flask/app.py", line 1630, in finalize_request
    response = self.make_response(rv)
  File "/anaconda3/lib/python3.6/site-packages/flask/app.py", line 1725, in make_response
    raise ValueError('View function did not return a response')
ValueError: View function did not return a response
2018-05-07 17:52:05,967 ERROR:             Exception on /users/piusraj/documents/python_files/sample8.jpg [GET] [in /anaconda3/lib/python3.6/site-packages/flask/app.py:1560]
Traceback (most recent call last):
  File "/anaconda3/lib/python3.6/site-packages/flask/app.py", line 1982, in wsgi_app
    response = self.full_dispatch_request()
  File "/anaconda3/lib/python3.6/site-packages/flask/app.py", line 1615, in full_dispatch_request
    return self.finalize_request(rv)
  File "/anaconda3/lib/python3.6/site-packages/flask/app.py", line 1630, in finalize_request
    response = self.make_response(rv)
  File "/anaconda3/lib/python3.6/site-packages/flask/app.py", line 1725, in make_response
    raise ValueError('View function did not return a response')
ValueError: View function did not return a response
2018-05-09 11:46:27,628 INFO:             errors [in app.py:71]
2018-05-09 11:46:43,013 ERROR:             Exception on /favicon.ico [GET] [in /anaconda3/lib/python3.6/site-packages/flask/app.py:1560]
Traceback (most recent call last):
  File "/anaconda3/lib/python3.6/site-packages/flask/app.py", line 1982, in wsgi_app
    response = self.full_dispatch_request()
  File "/anaconda3/lib/python3.6/site-packages/flask/app.py", line 1615, in full_dispatch_request
    return self.finalize_request(rv)
  File "/anaconda3/lib/python3.6/site-packages/flask/app.py", line 1630, in finalize_request
    response = self.make_response(rv)
  File "/anaconda3/lib/python3.6/site-packages/flask/app.py", line 1725, in make_response
    raise ValueError('View function did not return a response')
ValueError: View function did not return a response
2018-05-09 11:47:40,308 ERROR:             Exception on /users/piusraj/documents/python_files/sample2.jpg [GET] [in /anaconda3/lib/python3.6/site-packages/flask/app.py:1560]
Traceback (most recent call last):
  File "/anaconda3/lib/python3.6/site-packages/flask/app.py", line 1982, in wsgi_app
    response = self.full_dispatch_request()
  File "/anaconda3/lib/python3.6/site-packages/flask/app.py", line 1615, in full_dispatch_request
    return self.finalize_request(rv)
  File "/anaconda3/lib/python3.6/site-packages/flask/app.py", line 1630, in finalize_request
    response = self.make_response(rv)
  File "/anaconda3/lib/python3.6/site-packages/flask/app.py", line 1725, in make_response
    raise ValueError('View function did not return a response')
ValueError: View function did not return a response
2018-05-09 11:49:07,040 ERROR:             Exception on /favicon.ico [GET] [in /anaconda3/lib/python3.6/site-packages/flask/app.py:1560]
Traceback (most recent call last):
  File "/anaconda3/lib/python3.6/site-packages/flask/app.py", line 1982, in wsgi_app
    response = self.full_dispatch_request()
  File "/anaconda3/lib/python3.6/site-packages/flask/app.py", line 1615, in full_dispatch_request
    return self.finalize_request(rv)
  File "/anaconda3/lib/python3.6/site-packages/flask/app.py", line 1630, in finalize_request
    response = self.make_response(rv)
  File "/anaconda3/lib/python3.6/site-packages/flask/app.py", line 1725, in make_response
    raise ValueError('View function did not return a response')
ValueError: View function did not return a response
2018-05-09 11:49:15,370 ERROR:             Exception on /users/piusraj/documents/python_files/sample8.jpg [GET] [in /anaconda3/lib/python3.6/site-packages/flask/app.py:1560]
Traceback (most recent call last):
  File "/anaconda3/lib/python3.6/site-packages/flask/app.py", line 1982, in wsgi_app
    response = self.full_dispatch_request()
  File "/anaconda3/lib/python3.6/site-packages/flask/app.py", line 1615, in full_dispatch_request
    return self.finalize_request(rv)
  File "/anaconda3/lib/python3.6/site-packages/flask/app.py", line 1630, in finalize_request
    response = self.make_response(rv)
  File "/anaconda3/lib/python3.6/site-packages/flask/app.py", line 1725, in make_response
    raise ValueError('View function did not return a response')
ValueError: View function did not return a response
2018-05-09 11:49:18,922 ERROR:             Exception on /favicon.ico [GET] [in /anaconda3/lib/python3.6/site-packages/flask/app.py:1560]
Traceback (most recent call last):
  File "/anaconda3/lib/python3.6/site-packages/flask/app.py", line 1982, in wsgi_app
    response = self.full_dispatch_request()
  File "/anaconda3/lib/python3.6/site-packages/flask/app.py", line 1615, in full_dispatch_request
    return self.finalize_request(rv)
  File "/anaconda3/lib/python3.6/site-packages/flask/app.py", line 1630, in finalize_request
    response = self.make_response(rv)
  File "/anaconda3/lib/python3.6/site-packages/flask/app.py", line 1725, in make_response
    raise ValueError('View function did not return a response')
ValueError: View function did not return a response
2018-05-09 11:50:05,352 ERROR:             Exception on /users/piusraj/documents/python_files/sample5.jpg [GET] [in /anaconda3/lib/python3.6/site-packages/flask/app.py:1560]
Traceback (most recent call last):
  File "/anaconda3/lib/python3.6/site-packages/flask/app.py", line 1982, in wsgi_app
    response = self.full_dispatch_request()
  File "/anaconda3/lib/python3.6/site-packages/flask/app.py", line 1615, in full_dispatch_request
    return self.finalize_request(rv)
  File "/anaconda3/lib/python3.6/site-packages/flask/app.py", line 1630, in finalize_request
    response = self.make_response(rv)
  File "/anaconda3/lib/python3.6/site-packages/flask/app.py", line 1725, in make_response
    raise ValueError('View function did not return a response')
ValueError: View function did not return a response
2018-05-09 11:50:05,407 ERROR:             Exception on /favicon.ico [GET] [in /anaconda3/lib/python3.6/site-packages/flask/app.py:1560]
Traceback (most recent call last):
  File "/anaconda3/lib/python3.6/site-packages/flask/app.py", line 1982, in wsgi_app
    response = self.full_dispatch_request()
  File "/anaconda3/lib/python3.6/site-packages/flask/app.py", line 1615, in full_dispatch_request
    return self.finalize_request(rv)
  File "/anaconda3/lib/python3.6/site-packages/flask/app.py", line 1630, in finalize_request
    response = self.make_response(rv)
  File "/anaconda3/lib/python3.6/site-packages/flask/app.py", line 1725, in make_response
    raise ValueError('View function did not return a response')
ValueError: View function did not return a response
2018-05-09 11:50:17,854 ERROR:             Exception on /users/piusraj/documents/python_files/sample6.jpg [GET] [in /anaconda3/lib/python3.6/site-packages/flask/app.py:1560]
Traceback (most recent call last):
  File "/anaconda3/lib/python3.6/site-packages/flask/app.py", line 1982, in wsgi_app
    response = self.full_dispatch_request()
  File "/anaconda3/lib/python3.6/site-packages/flask/app.py", line 1615, in full_dispatch_request
    return self.finalize_request(rv)
  File "/anaconda3/lib/python3.6/site-packages/flask/app.py", line 1630, in finalize_request
    response = self.make_response(rv)
  File "/anaconda3/lib/python3.6/site-packages/flask/app.py", line 1725, in make_response
    raise ValueError('View function did not return a response')
ValueError: View function did not return a response
2018-05-09 11:56:39,353 ERROR:             Exception on /favicon.ico [GET] [in /anaconda3/lib/python3.6/site-packages/flask/app.py:1560]
Traceback (most recent call last):
  File "/anaconda3/lib/python3.6/site-packages/flask/app.py", line 1982, in wsgi_app
    response = self.full_dispatch_request()
  File "/anaconda3/lib/python3.6/site-packages/flask/app.py", line 1615, in full_dispatch_request
    return self.finalize_request(rv)
  File "/anaconda3/lib/python3.6/site-packages/flask/app.py", line 1630, in finalize_request
    response = self.make_response(rv)
  File "/anaconda3/lib/python3.6/site-packages/flask/app.py", line 1725, in make_response
    raise ValueError('View function did not return a response')
ValueError: View function did not return a response
2018-05-09 14:22:34,346 INFO:             errors [in app.py:71]
2018-05-09 14:25:25,138 ERROR:             Exception on /Users/piusraj/Downloads/EIDExtraction/EID.jpg [GET] [in /anaconda3/lib/python3.6/site-packages/flask/app.py:1560]
Traceback (most recent call last):
  File "/anaconda3/lib/python3.6/site-packages/flask/app.py", line 1982, in wsgi_app
    response = self.full_dispatch_request()
  File "/anaconda3/lib/python3.6/site-packages/flask/app.py", line 1615, in full_dispatch_request
    return self.finalize_request(rv)
  File "/anaconda3/lib/python3.6/site-packages/flask/app.py", line 1630, in finalize_request
    response = self.make_response(rv)
  File "/anaconda3/lib/python3.6/site-packages/flask/app.py", line 1725, in make_response
    raise ValueError('View function did not return a response')
ValueError: View function did not return a response
2018-05-09 14:26:22,560 ERROR:             Exception on /users/piusraj/documents/python_files/sample5.jpg [GET] [in /anaconda3/lib/python3.6/site-packages/flask/app.py:1560]
Traceback (most recent call last):
  File "/anaconda3/lib/python3.6/site-packages/flask/app.py", line 1982, in wsgi_app
    response = self.full_dispatch_request()
  File "/anaconda3/lib/python3.6/site-packages/flask/app.py", line 1615, in full_dispatch_request
    return self.finalize_request(rv)
  File "/anaconda3/lib/python3.6/site-packages/flask/app.py", line 1630, in finalize_request
    response = self.make_response(rv)
  File "/anaconda3/lib/python3.6/site-packages/flask/app.py", line 1725, in make_response
    raise ValueError('View function did not return a response')
ValueError: View function did not return a response
2018-05-09 14:27:04,309 ERROR:             Exception on /users/piusraj/documents/python_files/EID.jpg [GET] [in /anaconda3/lib/python3.6/site-packages/flask/app.py:1560]
Traceback (most recent call last):
  File "/anaconda3/lib/python3.6/site-packages/flask/app.py", line 1982, in wsgi_app
    response = self.full_dispatch_request()
  File "/anaconda3/lib/python3.6/site-packages/flask/app.py", line 1615, in full_dispatch_request
    return self.finalize_request(rv)
  File "/anaconda3/lib/python3.6/site-packages/flask/app.py", line 1630, in finalize_request
    response = self.make_response(rv)
  File "/anaconda3/lib/python3.6/site-packages/flask/app.py", line 1725, in make_response
    raise ValueError('View function did not return a response')
ValueError: View function did not return a response
2018-05-09 14:27:32,754 ERROR:             Exception on /users/piusraj/documents/python_files/Untitled.jpg [GET] [in /anaconda3/lib/python3.6/site-packages/flask/app.py:1560]
Traceback (most recent call last):
  File "/anaconda3/lib/python3.6/site-packages/flask/app.py", line 1982, in wsgi_app
    response = self.full_dispatch_request()
  File "/anaconda3/lib/python3.6/site-packages/flask/app.py", line 1615, in full_dispatch_request
    return self.finalize_request(rv)
  File "/anaconda3/lib/python3.6/site-packages/flask/app.py", line 1630, in finalize_request
    response = self.make_response(rv)
  File "/anaconda3/lib/python3.6/site-packages/flask/app.py", line 1725, in make_response
    raise ValueError('View function did not return a response')
ValueError: View function did not return a response
